Workbook

Sheet Pages
A1: ID | B1: Day | C1: Publish date | D1: URL | E1: Parent page | F1: WP page title | G1: H1 | H1: SEO title (Rank Math) | I1: SEO title length | J1: Meta description (Rank Math) | K1: Meta length | L1: Focus keyword | M1: Secondary keywords | N1: Page type | O1: Neha review scope | P1: Widgets on page | Q1: Words | R1: File to paste | S1: Status | T1: Live date
A2: 1 | B2: 1 | C2: 46318 | D2: https://wealthscale.ca/ | E2: (none) | F2: Home | G2: Compare Canadian Investing Accounts, Platforms and Banking | H2: Best Investment Platform Canada: Compare Brokers and Rates | I2: =LEN(H2) | J2: Best investment platform Canada: compare 13 online brokers, robo-advisors, savings rates and GICs, with 2026 limits such as the $7,000 TFSA limit. | K2: =LEN(J2) | L2: best investment platform canada | M2: best investing platform canada, online brokers canada, tfsa rrsp fhsa resp, best savings account canada, investment calculators canada | N2: home | O2: Yes | P2: account-chooser, tfsa-room, benefit-dates | Q2: 6667 | R2: pages-paste/001-home.html | S2: Not started
A3: 2 | B3: 1 | C3: 46318 | D3: https://wealthscale.ca/about/ | E3: (none) | F3: About | G3: About WealthScale | H3: WealthScale: About Our CPA Writer and CFA Charterholder | I3: =LEN(H3) | J3: WealthScale compares Canadian investing, savings and bank accounts on real costs. Written by a CPA with 15+ years in tax, reviewed by a CFA charterholder. | K3: =LEN(J3) | L3: wealthscale | M3: about wealthscale, wealthscale media inc, who runs wealthscale | N3: trust | O3: No | Q3: 2514 | R3: pages-paste/002-about.html | S3: Not started
A4: 3 | B4: 1 | C4: 46318 | D4: https://wealthscale.ca/about/sharad-gondaliya/ | E4: /about/ | F4: Sharad Gondaliya, CPA | G4: Sharad Gondaliya, CPA | H4: Sharad Gondaliya, CPA: Writer and Tax Reviewer | I4: =LEN(H4) | J4: Sharad Gondaliya, CPA writes WealthScale's pages. CPA Ontario No. 61040184, Certified Public Accountant in Washington and Montana, 15+ years in tax. | K4: =LEN(J4) | L4: sharad gondaliya cpa | M4: sharad gondaliya, sharadkumar gondaliya cpa, wealthscale cpa reviewer | N4: profile | O4: No | Q4: 1634 | R4: pages-paste/003-about-sharad-gondaliya.html | S4: Not started
A5: 4 | B5: 1 | C5: 46318 | D5: https://wealthscale.ca/editorial-standards/ | E5: (none) | F5: Editorial Standards | G5: Editorial Standards | H5: WealthScale Editorial Standards: How We Write and Check | I5: =LEN(H5) | J5: WealthScale editorial standards: pages written by a CPA with 15+ years in tax, investing pages reviewed by a CFA charterholder, rates re-checked weekly. | K5: =LEN(J5) | L5: wealthscale editorial standards | M5: how wealthscale writes, fact checking, financial review process | N5: trust | O5: No | Q5: 2528 | R5: pages-paste/004-editorial-standards.html | S5: Not started
A6: 5 | B6: 1 | C6: 46318 | D6: https://wealthscale.ca/how-we-make-money/ | E6: (none) | F6: How We Make Money | G6: How WealthScale Makes Money | H6: WealthScale Advertiser Disclosure: How We Make Money | I6: =LEN(H6) | J6: WealthScale advertiser disclosure: the site has 0 partner links today. Payment will never change which providers we include, their score or their order. | K6: =LEN(J6) | L6: wealthscale advertiser disclosure | M6: advertiser disclosure, affiliate disclosure, partner links | N6: trust | O6: No | Q6: 2106 | R6: pages-paste/005-how-we-make-money.html | S6: Not started
A7: 6 | B7: 1 | C7: 46318 | D7: https://wealthscale.ca/contact/ | E7: (none) | F7: Contact | G7: Contact WealthScale | H7: Contact WealthScale: Email, Corrections and Media Enquiries | I7: =LEN(H7) | J7: Contact WealthScale at info@wealthscale.ca for questions, corrections and media, or privacy@wealthscale.ca. We aim to reply within 2 business days. | K7: =LEN(J7) | L7: contact wealthscale | M7: wealthscale email, report an error, media enquiries | N7: trust | O7: No | Q7: 1787 | R7: pages-paste/006-contact.html | S7: Not started
A8: 9 | B8: 1 | C8: 46318 | D8: https://wealthscale.ca/methodology/brokers/ | E8: /methodology/ | F8: Broker Rating Methodology | G8: How We Rate Online Brokers and Robo-Advisors | H8: Broker Rating Methodology: How We Score Canadian Brokers | I8: =LEN(H8) | J8: Our broker rating methodology: six factors with cost weighted 35%, two priced investor profiles and every current score for brokers, robos and banks. | K8: =LEN(J8) | L8: broker rating methodology | M8: how we rank brokers, broker scoring, robo-advisor ratings | N8: trust | O8: Yes | P8: broker-match | Q8: 9601 | R8: pages-paste/009-methodology-brokers.html | S8: Not started
A9: 10 | B9: 1 | C9: 46318 | D9: https://wealthscale.ca/accounts/ | E9: (none) | F9: Investment Accounts | G9: Investment Accounts in Canada: TFSA, RRSP, FHSA, RESP and More | H9: Types of Investment Accounts Canada: TFSA, RRSP and More | I9: =LEN(H9) | J9: Types of investment accounts Canada: TFSA, RRSP, FHSA, RESP, RRIF, LIRA and non-registered compared, with 2026 limits like the $7,000 TFSA limit. | K9: =LEN(J9) | L9: types of investment accounts canada | M9: registered accounts canada, tfsa vs rrsp vs fhsa, registered vs non-registered | N9: hub | O9: Yes | P9: account-chooser, tfsa-room | Q9: 5619 | R9: pages-paste/010-accounts.html | S9: Not started
A10: 11 | B10: 1 | C10: 46318 | D10: https://wealthscale.ca/compare/ | E10: (none) | F10: Compare Online Brokers | G10: Compare Online Brokers and Investing Platforms in Canada | H10: Compare Online Brokers Canada: Fees, FX Costs and Scores | I10: =LEN(H10) | J10: Compare online brokers Canada-wide: 13 brokers scored on cost, FX and accounts. Interactive Brokers leads at 4.4 / 5, and seven charge $0 commissions. | K10: =LEN(J10) | L10: compare online brokers canada | M10: online brokerage comparison canada, investing platforms canada, discount brokers canada | N10: hub | O10: Yes | P10: broker-match, broker-cost | Q10: 5373 | R10: pages-paste/011-compare.html | S10: Not started
A11: 12 | B11: 1 | C11: 46318 | D11: https://wealthscale.ca/reviews/ | E11: (none) | F11: Reviews | G11: Canadian Broker, Bank and Platform Reviews | H11: Online Broker Reviews Canada: Scores, Verdicts and Costs | I11: =LEN(H11) | J11: Online broker reviews Canada: 21 reviews with scores and one-line verdicts, led by Interactive Brokers at 4.4 / 5. No provider pays for a review. | K11: =LEN(J11) | L11: online broker reviews canada | M11: questrade review, wealthsimple review, eq bank review, broker reviews | N11: hub | O11: Yes | P11: broker-match | Q11: 4531 | R11: pages-paste/012-reviews.html | S11: Not started
A12: 13 | B12: 1 | C12: 46318 | D12: https://wealthscale.ca/vs/ | E12: (none) | F12: Broker Comparison | G12: Broker Comparison: Any Two Platforms Side by Side | H12: Broker Comparison Canada: Any Two Platforms Side by Side | I12: =LEN(H12) | J12: Broker comparison Canada: every WealthScale versus page with category winners, a 19-row matrix of six brokers and yearly costs at 13 brokers. | K12: =LEN(J12) | L12: broker comparison canada | M12: wealthsimple vs questrade, tfsa vs rrsp, platform comparison | N12: hub | O12: Yes | P12: broker-cost | Q12: 4862 | R12: pages-paste/013-vs.html | S12: Not started
A13: 14 | B13: 1 | C13: 46318 | D13: https://wealthscale.ca/savings/ | E13: (none) | F13: Savings | G13: Best Places to Save Money in Canada: Savings Accounts and GICs | H13: Best Place to Save Money Canada: Top Savings and GIC Rates | I13: =LEN(H13) | J13: The best place to save money Canada-wide on October 22, 2026: 2.85% everyday savings with no paid plan, 3.85% 1-year GICs, CDIC rules and USD options. | K13: =LEN(J13) | L13: best place to save money canada | M13: high interest savings canada, gic rates canada, where to keep emergency fund | N13: hub | O13: Yes | P13: hisa-earnings, gic-calc, savings-goal | Q13: 4446 | R13: pages-paste/014-savings.html | S13: Not started
A14: 15 | B14: 1 | C14: 46318 | D14: https://wealthscale.ca/banking/ | E14: (none) | F14: Banking | G14: Bank Accounts in Canada Compared | H14: Best Bank Account Canada: Chequing, Savings and GICs | I14: =LEN(H14) | J14: Best bank account Canada guide: compare 20 chequing accounts, savings rates and GICs from online banks, fintechs and big banks. Top chequing score: 4.6 / 5. | K14: =LEN(J14) | L14: best bank account canada | M14: best chequing account canada, no fee bank account, online banks canada | N14: hub | O14: Yes | P14: chequing-cost | Q14: 4220 | R14: pages-paste/015-banking.html | S14: Not started
A15: 16 | B15: 1 | C15: 46318 | D15: https://wealthscale.ca/calculators/ | E15: (none) | F15: Calculators | G15: Investing, Savings and Tax Calculators | H15: Investment Calculators Canada: TFSA, RRSP and Tax Tools | I15: =LEN(H15) | J15: Investment calculators Canada: free TFSA, RRSP, FHSA, RESP, RRIF, income tax and compound interest tools using 2026 figures, like the $7,000 TFSA limit. | K15: =LEN(J15) | L15: investment calculators canada | M15: tfsa calculator, rrsp calculator, tax calculator canada 2026, compound interest calculator canada | N15: hub | O15: Yes | P15: income-tax | Q15: 5199 | R15: pages-paste/016-calculators.html | S15: Not started
A16: 17 | B16: 1 | C16: 46318 | D16: https://wealthscale.ca/benefits/ | E16: (none) | F16: CRA Benefit Payment Dates | G16: CRA Benefit Payment Dates | H16: CRA Payment Dates 2026: CPP, OAS, CGEB, CCB and OTB Calendar | I16: =LEN(H16) | J16: CRA payment dates 2026 for CPP, OAS, the CGEB, CCB, OTB and more. Next up: CPP and OAS on October 28, 2026, OTB on November 10 and CCB on November 20. | K16: =LEN(J16) | L16: cra payment dates 2026 | M16: cra benefit payment dates, cpp payment dates, gst payment dates, canada groceries and essentials benefit, ccb payment dates, ontario trillium benefit payment dates | N16: hub | O16: No | P16: benefit-dates, gst-credit, oas-clawback | Q16: 3862 | R16: pages-paste/017-benefits.html | S16: Not started
A17: 18 | B17: 1 | C17: 46318 | D17: https://wealthscale.ca/markets/ | E17: (none) | F17: International Investing | G17: International Investing From Canada: World Markets | H17: International Investing Canada: US and World Markets Guide | I17: =LEN(H17) | J17: International investing Canada guide: how to buy US and world stocks, USD accounts, 15% US withholding by account, and FX fees from US$2 on $10,000. | K17: =LEN(J17) | L17: international investing canada | M17: investing in us stocks from canada, global investing canada, foreign stocks canada | N17: hub | O17: Yes | P17: fx-cost, us-withholding | Q17: 4484 | R17: pages-paste/018-markets.html | S17: Not started
A18: 19 | B18: 1 | C18: 46318 | D18: https://wealthscale.ca/learn/ | E18: (none) | F18: Learn to Invest | G18: Investing for Beginners in Canada | H18: Investing for Beginners Canada: 7 Steps to Get Started | I18: =LEN(H18) | J18: Investing for beginners Canada: seven steps from emergency fund to first investment, plus 30 key terms. The 2026 TFSA limit is $7,000; RRSP limit $33,810. | K18: =LEN(J18) | L18: investing for beginners canada | M18: how to start investing canada, beginner investing, investing basics canada | N18: hub | O18: Yes | P18: compound-interest, account-chooser | Q18: 4791 | R18: pages-paste/019-learn.html | S18: Not started
A19: 20 | B19: 1 | C19: 46318 | D19: https://wealthscale.ca/calculators/tfsa-calculator/ | E19: /calculators/ | F19: TFSA Calculator | G19: TFSA Contribution Room Calculator | H19: TFSA Contribution Room Calculator: How Much Room You Have | I19: =LEN(H19) | J19: Our TFSA contribution room calculator adds every limit since 2009, up to $109,000, using your birth year, arrival year, deposits and withdrawals. | K19: =LEN(J19) | L19: tfsa contribution room calculator | M19: tfsa calculator, how much tfsa room do i have, tfsa room by age, tfsa limit calculator | N19: calculator | O19: Yes | P19: tfsa-room, tfsa-overcontribution, compound-interest | Q19: 3971 | R19: pages-paste/020-calculators-tfsa-calculator.html | S19: Not started
A20: 28 | B20: 1 | C20: 46318 | D20: https://wealthscale.ca/accounts/tfsa/ | E20: /accounts/ | F20: TFSA Guide | G20: TFSA Guide: How a Tax-Free Savings Account Works | H20: TFSA Guide: How a Tax-Free Savings Account Works in Canada | I20: =LEN(H20) | J20: A TFSA lets Canadian residents 18 and older grow money and withdraw it tax-free. The 2026 limit is $7,000 and total room since 2009 is $109,000. | K20: =LEN(J20) | L20: tfsa | M20: tax-free savings account, tfsa rules, tfsa limit 2026, tfsa withdrawal, what can you hold in a tfsa | N20: account-guide | O20: Yes | P20: tfsa-room, tfsa-overcontribution | Q20: 7278 | R20: pages-paste/028-accounts-tfsa.html | S20: Not started
A21: 101 | B21: 1 | C21: 46318 | D21: https://wealthscale.ca/about/neha-gupta/ | E21: /about/ | F21: Neha Gupta, CFA | G21: Neha Gupta, CFA | H21: Neha Gupta, CFA: Financial Reviewer | I21: =LEN(H21) | J21: Neha Gupta, CFA reviews WealthScale's investing pages. CFA charterholder in Winnipeg, in financial markets since 2005, with 2,600+ published articles. | K21: =LEN(J21) | L21: neha gupta cfa | M21: neha gupta cfa winnipeg, wealthscale financial reviewer, neha gupta whiteland real estate | N21: profile | O21: No | Q21: 1520 | R21: pages-paste/101-about-neha-gupta.html | S21: Not started
A22: 21 | B22: 2 | C22: 46319 | D22: https://wealthscale.ca/calculators/rrsp-calculator/ | E22: /calculators/ | F22: RRSP Calculator | G22: RRSP Tax Refund Calculator | H22: RRSP Calculator: Tax Refund and Savings by Province | I22: =LEN(H22) | J22: RRSP calculator for 2026: see the tax a contribution saves in your province. A $5,000 RRSP deduction saves $1,632.50 at $75,000 of income in Ontario. | K22: =LEN(J22) | L22: rrsp calculator | M22: rrsp tax refund calculator, rrsp tax savings calculator, how much tax will i save rrsp | N22: calculator | O22: Yes | P22: rrsp-refund, rrsp-room, rrsp-withdrawal | Q22: 4261 | R22: pages-paste/021-calculators-rrsp-calculator.html | S22: Not started
A23: 22 | B23: 2 | C23: 46319 | D23: https://wealthscale.ca/calculators/fhsa-calculator/ | E23: /calculators/ | F23: FHSA Calculator | G23: FHSA Calculator | H23: FHSA Calculator: Room, Carry-Forward and Tax Savings | I23: =LEN(H23) | J23: FHSA calculator: find your 2026 room, carry-forward and lifetime limit of $40,000, see what an $8,000 deduction saves in your province and plan a home buy. | K23: =LEN(J23) | L23: fhsa calculator | M23: fhsa contribution calculator, fhsa carry forward, fhsa room calculator | N23: calculator | O23: Yes | P23: fhsa-room, fhsa-eligibility, first-home | Q23: 4184 | R23: pages-paste/022-calculators-fhsa-calculator.html | S23: Not started
A24: 23 | B24: 2 | C24: 46319 | D24: https://wealthscale.ca/calculators/resp-calculator/ | E24: /calculators/ | F24: RESP Grant Calculator | G24: RESP Grant Calculator | H24: RESP Calculator: CESG, Learning Bond and Provincial Grants | I24: =LEN(H24) | J24: RESP calculator for 2026: estimate the 20% CESG, additional CESG, Canada Learning Bond and B.C. and Quebec grants, and see what it takes to collect $7,200. | K24: =LEN(J24) | L24: resp calculator | M24: resp grant calculator, cesg calculator, resp savings calculator | N24: calculator | O24: Yes | P24: resp-grant | Q24: 4223 | R24: pages-paste/023-calculators-resp-calculator.html | S24: Not started
A25: 24 | B25: 2 | C25: 46319 | D25: https://wealthscale.ca/calculators/rrif-calculator/ | E25: /calculators/ | F25: RRIF Minimum Withdrawal Calculator | G25: RRIF Minimum Withdrawal Calculator | H25: RRIF Calculator: Minimum Withdrawal by Age and Projection | I25: =LEN(H25) | J25: RRIF calculator for 2026: find your minimum withdrawal from the full factor table, from 4.00% at 65 to 20% at 95, plus withholding and a projection. | K25: =LEN(J25) | L25: rrif calculator | M25: rrif withdrawal calculator, rrif minimum calculator, rrif payment calculator | N25: calculator | O25: Yes | P25: rrif-minimum | Q25: 4204 | R25: pages-paste/024-calculators-rrif-calculator.html | S25: Not started
A26: 25 | B26: 2 | C26: 46319 | D26: https://wealthscale.ca/calculators/compound-interest-calculator/ | E26: /calculators/ | F26: Compound Interest Calculator | G26: Compound Interest Calculator | H26: Compound Interest Calculator Canada With Monthly Savings | I26: =LEN(H26) | J26: Compound interest calculator Canada: see how $10,000 at 5% grows to $16,470.09 in 10 years compounded monthly, with monthly savings, fees and tax. | K26: =LEN(J26) | L26: compound interest calculator canada | M26: compound interest canada, investment growth calculator, savings growth calculator | N26: calculator | O26: Yes | P26: compound-interest, savings-goal, fee-drag | Q26: 5490 | R26: pages-paste/025-calculators-compound-interest-calculator.html | S26: Not started
A27: 26 | B27: 2 | C27: 46319 | D27: https://wealthscale.ca/calculators/capital-gains-tax-calculator/ | E27: /calculators/ | F27: Capital Gains Tax Calculator | G27: Capital Gains Tax Calculator | H27: Capital Gains Tax Calculator Canada: Your Tax by Province | I27: =LEN(H27) | J27: Capital gains tax calculator Canada: half of a gain is taxable in 2026. See the tax on a $10,000 gain in each province, plus ACB, loss and reporting rules. | K27: =LEN(J27) | L27: capital gains tax calculator canada | M27: capital gains tax canada 2026, capital gains inclusion rate, how is capital gains taxed in canada | N27: calculator | O27: No | P27: capital-gains, dividend-tax, income-tax | Q27: 4587 | R27: pages-paste/026-calculators-capital-gains-tax-calculator.html | S27: Not started
A28: 27 | B28: 2 | C28: 46319 | D28: https://wealthscale.ca/calculators/currency-conversion-calculator/ | E28: /calculators/ | F28: Currency Conversion Fee Calculator | G28: Brokerage Currency Conversion Fee Calculator | H28: Currency Conversion Fee Calculator: Broker FX Costs Compared | I28: =LEN(H28) | J28: Currency conversion fee calculator for Canadian brokers: converting $10,000 costs US$2 at Interactive Brokers and $150 at a 1.5% broker. Compare all 13. | K28: =LEN(J28) | L28: currency conversion fee calculator | M28: broker fx fees canada, usd conversion fee, cad to usd broker fee | N28: calculator | O28: Yes | P28: fx-cost, norberts-gambit | Q28: 4496 | R28: pages-paste/027-calculators-currency-conversion-calculator.html | S28: Not started
A29: 29 | B29: 2 | C29: 46319 | D29: https://wealthscale.ca/accounts/tfsa-contribution-limit/ | E29: /accounts/ | F29: TFSA Contribution Limit | G29: TFSA Contribution Limit and Room by Year | H29: TFSA Limit 2026: Contribution Limit and Room by Year | I29: =LEN(H29) | J29: The TFSA limit 2026 is $7,000 and total room since 2009 is $109,000. See every annual limit, room by birth year and the status of the 2027 limit. | K29: =LEN(J29) | L29: tfsa limit 2026 | M29: tfsa contribution limit, tfsa limit by year, cumulative tfsa limit 2026, tfsa limit 2027 | N29: account-guide | O29: Yes | P29: tfsa-room | Q29: 5838 | R29: pages-paste/029-accounts-tfsa-contribution-limit.html | S29: Not started
A30: 30 | B30: 2 | C30: 46319 | D30: https://wealthscale.ca/accounts/tfsa-withdrawals/ | E30: /accounts/ | F30: TFSA Withdrawal Rules | G30: TFSA Withdrawal Rules | H30: TFSA Withdrawal Rules: Tax, Timing and Re-Contributing | I30: =LEN(H30) | J30: TFSA withdrawal rules: withdrawals are tax-free and return as room on January 1. Put money back too early and any excess is taxed at 1% a month. | K30: =LEN(J30) | L30: tfsa withdrawal rules | M30: tfsa withdrawal, re-contribute tfsa, tfsa withdrawal tax, how long tfsa withdrawal | N30: account-guide | O30: Yes | P30: tfsa-room, tfsa-overcontribution | Q30: 5622 | R30: pages-paste/030-accounts-tfsa-withdrawals.html | S30: Not started
A31: 31 | B31: 2 | C31: 46319 | D31: https://wealthscale.ca/accounts/us-stocks-in-tfsa/ | E31: /accounts/ | F31: US Stocks in a TFSA | G31: US Stocks in a TFSA: Withholding Tax and Currency Costs | H31: US Stocks in TFSA Accounts: Withholding Tax and FX Costs | I31: =LEN(H31) | J31: US stocks in TFSA accounts lose 15% of every US dividend to withholding tax, and many brokers charge 1.5% or more to convert. See the rules and the fixes. | K31: =LEN(J31) | L31: us stocks in tfsa | M31: us dividends tfsa withholding tax, w-8ben tfsa, usd tfsa | N31: account-guide | O31: Yes | P31: us-withholding, fx-cost | Q31: 8338 | R31: pages-paste/031-accounts-us-stocks-in-tfsa.html | S31: Not started
A32: 32 | B32: 2 | C32: 46319 | D32: https://wealthscale.ca/accounts/rrsp/ | E32: /accounts/ | F32: RRSP Guide | G32: RRSP Guide: How a Registered Retirement Savings Plan Works | H32: RRSP Guide: Rules, Limits, Deadlines and Withdrawals | I32: =LEN(H32) | J32: An RRSP lets you deduct contributions up to 18% of last year's earned income, to a $33,810 maximum for 2026. Rules, deadline, withdrawals and the HBP. | K32: =LEN(J32) | L32: rrsp | M32: registered retirement savings plan, rrsp rules, rrsp deadline 2026, spousal rrsp, rrsp withdrawal | N32: account-guide | O32: Yes | P32: rrsp-room, rrsp-refund, rrsp-withdrawal | Q32: 7944 | R32: pages-paste/032-accounts-rrsp.html | S32: Not started
A33: 33 | B33: 2 | C33: 46319 | D33: https://wealthscale.ca/accounts/rrsp-contribution-limit/ | E33: /accounts/ | F33: RRSP Contribution Limit | G33: RRSP Contribution Limit | H33: RRSP Contribution Limit 2026: $33,810 and How Room Works | I33: =LEN(H33) | J33: The RRSP contribution limit 2026 is the lesser of 18% of 2025 earned income and $33,810, minus pension adjustments, plus unused room. Find yours. | K33: =LEN(J33) | L33: rrsp contribution limit 2026 | M33: rrsp limit 2026, rrsp deduction limit, rrsp dollar limit by year, rrsp over contribution | N33: account-guide | O33: Yes | P33: rrsp-room | Q33: 6273 | R33: pages-paste/033-accounts-rrsp-contribution-limit.html | S33: Not started
... A81: 72 | B81: 4 | C81: 46321 | D81: https://wealthscale.ca/compare/best-lira-accounts/ | E81: /compare/ | F81: Best LIRA Accounts in Canada | G81: Best LIRA Accounts in Canada | H81: Best LIRA Account in Canada: 9 Brokers for LIRAs and LIFs | I81: =LEN(H81) | J81: Best LIRA account rankings: 9 brokers that hold LIRAs and LIFs, scored on fees and features. Questrade leads at 4.0 / 5; watch $100 small-balance fees. | K81: =LEN(J81) | L81: best lira account | M81: self directed lira, lira to lif | N81: account-listing | O81: Yes | P81: rrif-minimum | Q81: 8008 | R81: pages-paste/072-compare-best-lira-accounts.html | S81: Not started
A82: 7 | B82: 5 | C82: 46322 | D82: https://wealthscale.ca/privacy-policy/ | E82: (none) | F82: Privacy Policy | G82: Privacy Policy | H82: WealthScale Privacy Policy: How We Handle Your Information | I82: =LEN(H82) | J82: WealthScale privacy policy: what WealthScale Media Inc. collects, why, and your rights. Calculator inputs stay in your browser and are not sent to us. | K82: =LEN(J82) | L82: wealthscale privacy policy | M82: wealthscale privacy, personal information, cookies | N82: legal | O82: No | Q82: 2465 | R82: pages-paste/007-privacy-policy.html | S82: Not started
A83: 8 | B83: 5 | C83: 46322 | D83: https://wealthscale.ca/terms-of-use/ | E83: (none) | F83: Terms of Use and Disclaimer | G83: Terms of Use and Disclaimer | H83: WealthScale Terms of Use and Disclaimer for Readers | I83: =LEN(H83) | J83: WealthScale terms of use and disclaimer: general information only, not financial, tax or legal advice. Calculators give estimates and rates can change. | K83: =LEN(J83) | L83: wealthscale terms of use | M83: wealthscale disclaimer, terms and conditions | N83: legal | O83: No | Q83: 2135 | R83: pages-paste/008-terms-of-use.html | S83: Not started
A84: 73 | B84: 5 | C84: 46322 | D84: https://wealthscale.ca/banking/best-chequing-accounts/ | E84: /banking/ | F84: Best Chequing Accounts in Canada | G84: Best Chequing Accounts in Canada | H84: Best Chequing Account Canada 2026: 20 Accounts Ranked | I84: =LEN(H84) | J84: Best chequing account Canada rankings for 2026: 20 accounts scored on fees, interest, ATMs and CDIC. EQ Bank leads at 4.6 / 5 with 2.75% on direct deposit. | K84: =LEN(J84) | L84: best chequing account canada | M84: chequing account canada, best bank account canada, high interest chequing | N84: best-of | O84: Yes | P84: chequing-cost | Q84: 12450 | R84: pages-paste/073-banking-best-chequing-accounts.html | S84: Not started
A85: 74 | B85: 5 | C85: 46322 | D85: https://wealthscale.ca/banking/best-no-fee-chequing-accounts/ | E85: /banking/ | F85: Best No-Fee Chequing Accounts in Canada | G85: Best No-Fee Chequing Accounts in Canada | H85: No Fee Chequing Account Canada 2026: The 8 Best Ranked | I85: =LEN(H85) | J85: No fee chequing account rankings for 2026: 8 accounts with a $0 monthly fee, scored. EQ Bank leads at 4.6 / 5 and pays 2.75% with pay direct deposit. | K85: =LEN(J85) | L85: no fee chequing account | M85: free chequing account canada, no monthly fee bank account | N85: best-of | O85: Yes | P85: chequing-cost | Q85: 8330 | R85: pages-paste/074-banking-best-no-fee-chequing-accounts.html | S85: Not started
A86: 75 | B86: 5 | C86: 46322 | D86: https://wealthscale.ca/savings/high-interest-savings-accounts/ | E86: /savings/ | F86: Best High-Interest Savings Accounts | G86: Best High-Interest Savings Accounts in Canada | H86: Best High Interest Savings Account Canada: 2026 Rates | I86: =LEN(H86) | J86: Compare the best high interest savings account Canada offers in 2026: Saven pays 2.85% with no fee, Oaken 2.80% with CDIC cover. Rates checked Oct 22. | K86: =LEN(J86) | L86: best high interest savings account canada | M86: high interest savings account canada, best savings rates canada, hisa rates | N86: rates | O86: Yes | P86: hisa-earnings, savings-goal | Q86: 9415 | R86: pages-paste/075-savings-high-interest-savings-accounts.html | S86: Not started
A87: 76 | B87: 5 | C87: 46322 | D87: https://wealthscale.ca/savings/usd-savings-accounts/ | E87: /savings/ | F87: Best USD Savings Accounts | G87: Best USD Savings Accounts in Canada | H87: USD Savings Account Canada: Best US Dollar Savings Rates | I87: =LEN(H87) | J87: Compare every USD savings account Canada banks publish: EQ Bank pays 2.50%, big banks 0.250% or less, plus fees, CDIC rules and tax. Checked October 22. | K87: =LEN(J87) | L87: usd savings account canada | M87: us dollar savings account canada, usd hisa | N87: rates | O87: Yes | P87: hisa-earnings[usd] | Q87: 6808 | R87: pages-paste/076-savings-usd-savings-accounts.html | S87: Not started
...

Sheet Schedule
A1: Day | B1: Date | C1: Pages planned | D1: Live | E1: Remaining | F1: Words planned
A2: 1 | B2: 46318 | C2: =COUNTIF(Pages!B$2:B$102,A2) | D2: =COUNTIFS(Pages!B$2:B$102,A2,Pages!S$2:S$102,"Live") | E2: =C2-D2 | F2: =SUMIF(Pages!B$2:B$102,A2,Pages!Q$2:Q$102)
A3: 2 | B3: 46319 | C3: =COUNTIF(Pages!B$2:B$102,A3) | D3: =COUNTIFS(Pages!B$2:B$102,A3,Pages!S$2:S$102,"Live") | E3: =C3-D3 | F3: =SUMIF(Pages!B$2:B$102,A3,Pages!Q$2:Q$102)
A4: 3 | B4: 46320 | C4: =COUNTIF(Pages!B$2:B$102,A4) | D4: =COUNTIFS(Pages!B$2:B$102,A4,Pages!S$2:S$102,"Live") | E4: =C4-D4 | F4: =SUMIF(Pages!B$2:B$102,A4,Pages!Q$2:Q$102)
A5: 4 | B5: 46321 | C5: =COUNTIF(Pages!B$2:B$102,A5) | D5: =COUNTIFS(Pages!B$2:B$102,A5,Pages!S$2:S$102,"Live") | E5: =C5-D5 | F5: =SUMIF(Pages!B$2:B$102,A5,Pages!Q$2:Q$102)
A6: 5 | B6: 46322 | C6: =COUNTIF(Pages!B$2:B$102,A6) | D6: =COUNTIFS(Pages!B$2:B$102,A6,Pages!S$2:S$102,"Live") | E6: =C6-D6 | F6: =SUMIF(Pages!B$2:B$102,A6,Pages!Q$2:Q$102)
A7: Total | C7: =SUM(C2:C6) | D7: =SUM(D2:D6) | E7: =SUM(E2:E6) | F7: =SUM(F2:F6)

Sheet Widgets
A1: Widget | B1: What it does | C1: Pages using it (IDs) | D1: Number of pages
A2: tfsa-room | B2: TFSA room from birth year, year became a resident, non-resident years, contributions and withdrawals; shows room now, room next January 1, and a year-by-year table | C2: 1, 10, 20, 28, 29, 30, 52, 56 | D2: =IF(C2="",0,LEN(C2)-LEN(SUBSTITUTE(C2,",",""))+1)
A3: tfsa-overcontribution | B3: 1% a month tax on an excess TFSA amount | C3: 20, 28, 30, 98 | D3: =IF(C3="",0,LEN(C3)-LEN(SUBSTITUTE(C3,",",""))+1)
A4: rrsp-room | B4: 2026 RRSP deduction limit from earned income, pension adjustment, carry-forward | C4: 21, 32, 33 | D4: =IF(C4="",0,LEN(C4)-LEN(SUBSTITUTE(C4,",",""))+1)
A5: rrsp-refund | B5: Tax saved by an RRSP deduction in any province, 2026 brackets | C5: 21, 32, 57, 91 | D5: =IF(C5="",0,LEN(C5)-LEN(SUBSTITUTE(C5,",",""))+1)
A6: income-tax | B6: 2026 federal and provincial tax, marginal rates by income type | C6: 16, 24, 26 | D6: =IF(C6="",0,LEN(C6)-LEN(SUBSTITUTE(C6,",",""))+1)
A7: capital-gains | B7: Tax on a capital gain, loss carry-forward | C7: 26 | D7: =IF(C7="",0,LEN(C7)-LEN(SUBSTITUTE(C7,",",""))+1)
A8: dividend-tax | B8: Tax on eligible and other than eligible dividends | C8: 26 | D8: =IF(C8="",0,LEN(C8)-LEN(SUBSTITUTE(C8,",",""))+1)
A9: fhsa-room | B9: FHSA participation room by year opened and contributions, lifetime room, closing date | C9: 22, 35, 51, 58, 93 | D9: =IF(C9="",0,LEN(C9)-LEN(SUBSTITUTE(C9,",",""))+1)
A10: fhsa-eligibility | B10: Four-question FHSA eligibility check | C10: 22, 35, 36 | D10: =IF(C10="",0,LEN(C10)-LEN(SUBSTITUTE(C10,",",""))+1)
A11: resp-grant | B11: CESG, Additional CESG, Canada Learning Bond, BC and Quebec grants, projection to 17 | C11: 23, 37, 38, 59, 70 | D11: =IF(C11="",0,LEN(C11)-LEN(SUBSTITUTE(C11,",",""))+1)
A12: rrif-minimum | B12: RRIF minimum withdrawal and projection | C12: 24, 39, 57, 71, 72 | D12: =IF(C12="",0,LEN(C12)-LEN(SUBSTITUTE(C12,",",""))+1)
A13: hbp-repayment | B13: Home Buyers' Plan repayment schedule | C13: 34, 92 | D13: =IF(C13="",0,LEN(C13)-LEN(SUBSTITUTE(C13,",",""))+1)
... A44: table-filter | B44: Wrap a static table: `<div data-ws-widget="table-filter"><div class="ws-table-wrap"><table>...</table></div></div>` adds search and sorting | C44: 10, 11, 15, 18, 19, 21, 22, 24, 33, 36, 39, 47, 53, 54, 55, 56, 57, 58, 59, 60, 61, 62, 63, 64, 65, 66, 67, 68, 69, 70, 71, 72, 73, 74, 98 | D44: =IF(C44="",0,LEN(C44)-LEN(SUBSTITUTE(C44,",",""))+1)

Sheet Open items
A1: # | B1: Item | C1: Owner | D1: Why it matters | E1: Status
A2: 1 | B2: Confirm the two rates the grocery benefit calculator uses: single supplement phase-in of 2% of net income above $11,564, and reduction of 5% of family net income above $46,432. CRA pages opened showed the thresholds but not the rates. Page text does not state the rates. | C2: Sharad | D2: The calculator shows an estimate for incomes above the thresholds. | E2: Open
A3: 2 | B3: Confirm the wording that RRSPs, RRIFs, LIRAs and LIFs are exempt from US withholding on dividends from US-listed securities held directly (Canada-US tax treaty, Article XXI), and that TFSAs, FHSAs and RESPs are not. | C3: Sharad | D3: Stated on the US stocks, TFSA, RRSP and listing pages and in the US withholding calculator. | E3: Open
A4: 3 | B4: Confirm the 2026 capital gains inclusion rate of one half (CRA confirms one half through 2025; the proposed two-thirds increase did not take effect). | C4: Sharad | D4: Used by the capital gains and income tax calculators and stated on page 26. | E4: Open
A5: 4 | B5: Manitoba 2026 bracket thresholds: CRA payroll tables show $47,000 and $100,000; CRA's rates page shows $47,564 and $101,200. Calculators use the payroll values with a note; Manitoba is left out of computed tables. | C5: Sharad | D5: Decide which figure to publish once the 2026 MB428 form is out. | E5: Open
A6: 5 | B6: Provincial dividend tax credit rates are confirmed only for Ontario, British Columbia and Quebec. The dividend calculators show a 'being confirmed' note for the other 10 provinces and territories. | C6: Sharad | D6: Adding the 10 rates turns the dividend calculators on for every province. | E6: Open
A7: 6 | B7: Form and line references used on pages but not in the research registers: Schedule 7 (HBP and RRSP), lines 20800 and 26000, T4 box 52, Forms T2033, T2220, T1213, T3012A and the TFSA Return. | C7: Sharad | D7: Quick CPA check of each reference. | E7: Open
A8: 7 | B8: Core rules stated as rules without a register entry: TFSA contributions are not deductible; TFSA withdrawals are not income and do not affect benefits; qualifying FHSA withdrawals are tax-free; RESP educational assistance payments are taxed to the student; RRSP withdrawals do not restore room. The full list of rules left in for CPA review, page by page, is in factcheck-notes.md in this package. | C8: Sharad | D8: Standard rules, listed for completeness of the CPA review. | E8: Open
A9: 8 | B9: Quebec provincial withholding on RRSP lump-sum withdrawals: one register shows 14%, the other marks it unverified. Pages state only that Quebec also withholds provincial tax. | C9: Sharad | D9: Add the rate to the RRSP pages once confirmed. | E9: Open
A10: 9 | B10: Neha's profile: the approved SEO title is 35 characters (shorter than the 45 to 62 used elsewhere) and her approved schema dates are October 25, 2026 while the page goes live October 23. | C10: Sharad | D10: Keep as approved or allow a longer title and the October 23 date. | E10: Open
A11: 10 | B11: Sharad's approved bio: one word changed, 'Canada.ca' to 'the Government of Canada', to follow the no-outside-sites rule. | C11: Sharad | D11: Revert if word-for-word wording matters more. | E11: Open
A12: 11 | B12: Neha's headshot is 400 x 400 pixels, below the 800 x 800 minimum in her package. Request a larger original from Neha in the Upwork thread. | C12: Navneet | D12: Sharper image on the profile page and in search results. | E12: Done Oct 22: Sharad confirmed to use the existing headshot (400 and 128 px, uploaded to /ws/people/)
A13: 12 | B13: Export Sharad's existing headshot as sharad-gondaliya-cpa-128.jpg and sharad-gondaliya-cpa-400.jpg (square, metadata removed) and upload to /wp-content/uploads/ws/people/. | C13: Navneet | D13: Every page shows his photo in the byline and experts block. | E13: Open
... A21: 20 | B21: Load Google Analytics (or any analytics tag) only after the visitor accepts cookies. The calculators send a 'calculator used' event with the calculator name only, and the privacy policy promises consent first. The cookie banner must be live before Day 1 pages go public. | C21: Navneet | D21: The privacy policy's consent promise must hold on launch day. | E21: Open
