Workbook

Sheet Pages
A1: ID | B1: Day | C1: Publish date | D1: URL | E1: Parent page | F1: WP page title | G1: H1 | H1: SEO title (Rank Math) | I1: SEO title length | J1: Meta description (Rank Math) | K1: Meta length | L1: Focus keyword | M1: Secondary keywords | N1: Page type | O1: Neha review scope | P1: Widgets on page | Q1: Words | R1: File to paste | S1: Status | T1: Live date
A2: 102 | B2: 6 | C2: 46325 | D2: https://wealthscale.ca/tax/ | E2: (none) | F2: Canadian Income Tax Guide | G2: Canadian Income Tax Guide 2026: Brackets, Rates and Calculators | H2: Canadian Income Tax Guide: Brackets, Rates and Calculators | I2: =LEN(H2) -> 58 | J2: Canadian income tax guide: federal brackets from 14% to 33%, every provincial rate, payroll deductions, investment income rules and calculators for 2026. | K2: =LEN(J2) -> 153 | L2: canadian income tax | M2: income tax canada 2026, tax brackets canada, how much tax will i pay canada | N2: hub | O2: No | P2: income-tax, take-home-pay, rrsp-refund, account-chooser | Q2: 4088 | R2: pages-paste/102-tax.html | S2: Not started
A3: 103 | B3: 6 | C3: 46325 | D3: https://wealthscale.ca/calculators/income-tax-calculator/ | E3: /calculators/ | F3: Income Tax Calculator Canada 2026 | G3: Income Tax Calculator Canada 2026 | H3: Income Tax Calculator Canada 2026: Federal and Provincial | I3: =LEN(H3) -> 57 | J3: Income tax calculator Canada 2026: federal and provincial tax, average and marginal rates in all 13 regions. $80,000 in Ontario pays $15,497.25. | K3: =LEN(J3) -> 144 | L3: income tax calculator canada | M3: canada tax calculator 2026, how much tax do i pay, marginal tax rate calculator, average tax rate canada | N3: calculator | O3: No | P3: income-tax, take-home-pay, rrsp-refund, table-filter | Q3: 6257 | R3: pages-paste/103-calculators-income-tax-calculator.html | S3: Not started
A4: 104 | B4: 6 | C4: 46325 | D4: https://wealthscale.ca/tax/federal-tax-brackets/ | E4: /tax/ | F4: Federal Tax Brackets 2026 | G4: Federal Tax Brackets 2026 | H4: Federal Tax Brackets 2026: Canada's 14% to 33% Rates | I4: =LEN(H4) -> 52 | J4: Federal tax brackets 2026: 14% up to $58,523, then 20.5%, 26%, 29% and 33% over $258,482, with a $16,452 basic personal amount. See tax at any income. | K4: =LEN(J4) -> 150 | L4: federal tax brackets 2026 | M4: federal income tax rates 2026, canada tax brackets 2026, federal basic personal amount 2026 | N4: tax-guide | O4: No | P4: income-tax, take-home-pay, rrsp-refund | Q4: 5840 | R4: pages-paste/104-tax-federal-tax-brackets.html | S4: Not started
A5: 105 | B5: 6 | C5: 46325 | D5: https://wealthscale.ca/tax/marginal-tax-rates/ | E5: /tax/ | F5: Marginal Tax Rates in Canada 2026 | G5: Marginal Tax Rates in Canada 2026 by Province | H5: Marginal Tax Rate Canada 2026: Every Province Compared | I5: =LEN(H5) -> 54 | J5: Marginal tax rate Canada 2026: combined federal and provincial rates at every bracket edge, top rates of 44.50% to 54.80%, and gain and dividend rates. | K5: =LEN(J5) -> 151 | L5: marginal tax rate canada | M5: combined marginal tax rates 2026, top marginal tax rate canada, marginal tax rate ontario | N5: tax-guide | O5: No | P5: income-tax, capital-gains, dividend-tax, rrsp-refund | Q5: 8928 | R5: pages-paste/105-tax-marginal-tax-rates.html | S5: Not started
A6: 106 | B6: 6 | C6: 46325 | D6: https://wealthscale.ca/tax/ontario-tax-brackets/ | E6: /tax/ | F6: Ontario Tax Brackets 2026 | G6: Ontario Income Tax Calculator and 2026 Tax Brackets | H6: Ontario Tax Brackets 2026: Income Tax Calculator and Rates | I6: =LEN(H6) -> 58 | J6: Ontario tax brackets 2026: 5.05% on the first $53,891 up to 13.16% over $220,000, a $12,989 basic personal amount and a 53.53% top combined rate. | K6: =LEN(J6) -> 145 | L6: ontario tax brackets 2026 | M6: ontario income tax calculator, ontario tax rates 2026, ontario basic personal amount 2026 | N6: province-tax | O6: No | P6: income-tax[ON], take-home-pay[ON], rrsp-refund[ON], capital-gains[ON] | Q6: 7214 | R6: pages-paste/106-tax-ontario-tax-brackets.html | S6: Not started
A7: 107 | B7: 6 | C7: 46325 | D7: https://wealthscale.ca/tax/british-columbia-tax-brackets/ | E7: /tax/ | F7: British Columbia Tax Brackets 2026 | G7: British Columbia Income Tax Calculator and 2026 Tax Brackets | H7: British Columbia Tax Brackets 2026: Calculator and Rates | I7: =LEN(H7) -> 56 | J7: British Columbia tax brackets 2026: seven rates from 5.6% to 20.5%, a $13,216 basic personal amount, a $690 tax reduction and a 53.50% top combined rate. | K7: =LEN(J7) -> 153 | L7: british columbia tax brackets 2026 | M7: british columbia income tax calculator, british columbia tax rates 2026, british columbia basic personal amount 2026 | N7: province-tax | O7: No | P7: income-tax[BC], take-home-pay[BC], rrsp-refund[BC], capital-gains[BC] | Q7: 6433 | R7: pages-paste/107-tax-british-columbia-tax-brackets.html | S7: Not started
A8: 108 | B8: 6 | C8: 46325 | D8: https://wealthscale.ca/tax/alberta-tax-brackets/ | E8: /tax/ | F8: Alberta Tax Brackets 2026 | G8: Alberta Income Tax Calculator and 2026 Tax Brackets | H8: Alberta Tax Brackets 2026: Income Tax Calculator and Rates | I8: =LEN(H8) -> 58 | J8: Alberta tax brackets 2026: 8% on the first $61,200 up to 15% over $370,220, a $22,769 basic personal amount and a 48% top combined rate, with a calculator. | K8: =LEN(J8) -> 155 | L8: alberta tax brackets 2026 | M8: alberta income tax calculator, alberta tax rates 2026, alberta basic personal amount 2026 | N8: province-tax | O8: No | P8: income-tax[AB], take-home-pay[AB], rrsp-refund[AB], capital-gains[AB] | Q8: 6005 | R8: pages-paste/108-tax-alberta-tax-brackets.html | S8: Not started
A9: 109 | B9: 6 | C9: 46325 | D9: https://wealthscale.ca/tax/quebec-tax-brackets/ | E9: /tax/ | F9: Quebec Tax Brackets 2026 | G9: Quebec Income Tax Calculator and 2026 Tax Brackets | H9: Quebec Tax Brackets 2026: Income Tax Calculator and Rates | I9: =LEN(H9) -> 57 | J9: Quebec tax brackets 2026: 14% on the first $54,345 up to 25.75% over $132,245, an $18,952 basic personal amount and a 16.5% abatement of federal tax. | K9: =LEN(J9) -> 149 | L9: quebec tax brackets 2026 | M9: quebec income tax calculator, quebec tax rates 2026, quebec basic personal amount 2026 | N9: province-tax | O9: No | P9: income-tax[QC], take-home-pay[QC], rrsp-refund[QC], capital-gains[QC] | Q9: 6337 | R9: pages-paste/109-tax-quebec-tax-brackets.html | S9: Not started
A10: 110 | B10: 6 | C10: 46325 | D10: https://wealthscale.ca/tax/manitoba-tax-brackets/ | E10: /tax/ | F10: Manitoba Tax Brackets 2026 | G10: Manitoba Income Tax Calculator and 2026 Tax Brackets | H10: Manitoba Tax Brackets 2026: Rates, BPA and Calculator | I10: =LEN(H10) -> 53 | J10: Manitoba tax brackets 2026: 10.8% to $47,000, 12.75% to $100,000 and 17.4% above, frozen since 2024. Basic personal amount $15,780. Calculator inside. | K10: =LEN(J10) -> 150 | L10: manitoba tax brackets 2026 | M10: manitoba income tax calculator, manitoba tax rates 2026, manitoba basic personal amount 2026 | N10: province-tax | O10: No | P10: income-tax[MB], take-home-pay[MB], rrsp-refund[MB], capital-gains[MB], table-filter | Q10: 6459 | R10: pages-paste/110-tax-manitoba-tax-brackets.html | S10: Not started
A11: 111 | B11: 6 | C11: 46325 | D11: https://wealthscale.ca/tax/saskatchewan-tax-brackets/ | E11: /tax/ | F11: Saskatchewan Tax Brackets 2026 | G11: Saskatchewan Income Tax Calculator and 2026 Tax Brackets | H11: Saskatchewan Tax Brackets 2026: Rates and Calculator | I11: =LEN(H11) -> 52 | J11: Saskatchewan tax brackets 2026: 10.5% to $54,532, 12.5% to $155,805, 14.5% above. Basic personal amount $20,381. Calculator and tax tables inside. | K11: =LEN(J11) -> 146 | L11: saskatchewan tax brackets 2026 | M11: saskatchewan income tax calculator, saskatchewan tax rates 2026, saskatchewan basic personal amount 2026 | N11: province-tax | O11: No | P11: income-tax[SK], take-home-pay[SK], rrsp-refund[SK], capital-gains[SK], table-filter | Q11: 5468 | R11: pages-paste/111-tax-saskatchewan-tax-brackets.html | S11: Not started
A12: 112 | B12: 6 | C12: 46325 | D12: https://wealthscale.ca/tax/nova-scotia-tax-brackets/ | E12: /tax/ | F12: Nova Scotia Tax Brackets 2026 | G12: Nova Scotia Income Tax Calculator and 2026 Tax Brackets | H12: Nova Scotia Tax Brackets 2026: Rates and Tax Calculator | I12: =LEN(H12) -> 55 | J12: Nova Scotia tax brackets 2026: five rates from 8.79% to 21%, an $11,932 basic personal amount and a 54% top combined rate. Calculator and tax tables. | K12: =LEN(J12) -> 149 | L12: nova scotia tax brackets 2026 | M12: nova scotia income tax calculator, nova scotia tax rates 2026, nova scotia basic personal amount 2026 | N12: province-tax | O12: No | P12: income-tax[NS], take-home-pay[NS], rrsp-refund[NS], capital-gains[NS], dividend-tax[NS], table-filter | Q12: 5439 | R12: pages-paste/112-tax-nova-scotia-tax-brackets.html | S12: Not started
A13: 113 | B13: 6 | C13: 46325 | D13: https://wealthscale.ca/tax/new-brunswick-tax-brackets/ | E13: /tax/ | F13: New Brunswick Tax Brackets 2026 | G13: New Brunswick Income Tax Calculator and 2026 Tax Brackets | H13: New Brunswick Tax Brackets 2026: Rates and Calculator | I13: =LEN(H13) -> 53 | J13: New Brunswick tax brackets 2026: 9.4% to $52,333, then 14%, 16% and 19.5% over $193,861. Basic personal amount $13,664. Calculator and tax tables. | K13: =LEN(J13) -> 146 | L13: new brunswick tax brackets 2026 | M13: new brunswick income tax calculator, new brunswick tax rates 2026, new brunswick basic personal amount 2026 | N13: province-tax | O13: No | P13: income-tax[NB], take-home-pay[NB], rrsp-refund[NB], capital-gains[NB], dividend-tax[NB], table-filter | Q13: 5285 | R13: pages-paste/113-tax-new-brunswick-tax-brackets.html | S13: Not started
... A101: 201 | B101: 10 | C101: 46329 | D101: https://wealthscale.ca/learn/how-to-file-taxes-online/ | E101: /learn/ | F101: How to File Your Taxes Online in Canada | G101: How to File Your Taxes Online in Canada | H101: How to File Taxes Online Canada: NETFILE Step by Step | I101: =LEN(H101) -> 53 | J101: This how to file taxes online Canada guide covers NETFILE step by step, free software from $0, the slips you need and the April 30, 2027 filing deadline. | K101: =LEN(J101) -> 153 | L101: how to file taxes online canada | M101: netfile canada, file taxes for free canada, tax software canada | N101: learn-guide | O101: No | P101: tax-software-picker, income-tax, rrsp-refund, countdown | Q101: 6250 | R101: pages-paste/201-learn-how-to-file-taxes-online.html | S101: Not started

Sheet Schedule
A1: Day | B1: Date | C1: Work | D1: Pages planned | E1: Done or live | F1: Remaining | G1: Words
A2: Re-do 1 | B2: 46322 | C2: Set-up check, three replacement pages and redirects, first 101 pages part 1 | D2: =COUNTIF('First 101 pages (latest)'!A$2:A$102,B2) -> 52 | E2: =COUNTIFS('First 101 pages (latest)'!A$2:A$102,B2,'First 101 pages (latest)'!M$2:M$102,"Done") -> 52 | F2: =D2-E2 -> 0 | G2: =SUMIF('First 101 pages (latest)'!A$2:A$102,B2,'First 101 pages (latest)'!L$2:L$102) -> 313828
A3: Re-do 2 | B3: 46323 | C3: First 101 pages part 2 | D3: =COUNTIF('First 101 pages (latest)'!A$2:A$102,B3) -> 49 | E3: =COUNTIFS('First 101 pages (latest)'!A$2:A$102,B3,'First 101 pages (latest)'!M$2:M$102,"Done") -> 49 | F3: =D3-E3 -> 0 | G3: =SUMIF('First 101 pages (latest)'!A$2:A$102,B3,'First 101 pages (latest)'!L$2:L$102) -> 409793
A4: Check | B4: 46324 | C4: Check all 101 pages; no new pages | D4: 0 | E4: 0 | F4: 0 | G4: 0
A5: 6 | B5: 46325 | C5: New pages 102 to 201 | D5: =COUNTIF(Pages!B$2:B$101,A5) -> 20 | E5: =COUNTIFS(Pages!B$2:B$101,A5,Pages!S$2:S$101,"Live") -> 0 | F5: =D5-E5 -> 20 | G5: =SUMIF(Pages!B$2:B$101,A5,Pages!Q$2:Q$101) -> 142771
A6: 7 | B6: 46326 | C6: New pages 102 to 201 | D6: =COUNTIF(Pages!B$2:B$101,A6) -> 20 | E6: =COUNTIFS(Pages!B$2:B$101,A6,Pages!S$2:S$101,"Live") -> 0 | F6: =D6-E6 -> 20 | G6: =SUMIF(Pages!B$2:B$101,A6,Pages!Q$2:Q$101) -> 135345
A7: 8 | B7: 46327 | C7: New pages 102 to 201 | D7: =COUNTIF(Pages!B$2:B$101,A7) -> 20 | E7: =COUNTIFS(Pages!B$2:B$101,A7,Pages!S$2:S$101,"Live") -> 0 | F7: =D7-E7 -> 20 | G7: =SUMIF(Pages!B$2:B$101,A7,Pages!Q$2:Q$101) -> 145918
A8: 9 | B8: 46328 | C8: New pages 102 to 201 | D8: =COUNTIF(Pages!B$2:B$101,A8) -> 20 | E8: =COUNTIFS(Pages!B$2:B$101,A8,Pages!S$2:S$101,"Live") -> 0 | F8: =D8-E8 -> 20 | G8: =SUMIF(Pages!B$2:B$101,A8,Pages!Q$2:Q$101) -> 111648
A9: 10 | B9: 46329 | C9: New pages 102 to 201 | D9: =COUNTIF(Pages!B$2:B$101,A9) -> 20 | E9: =COUNTIFS(Pages!B$2:B$101,A9,Pages!S$2:S$101,"Live") -> 0 | F9: =D9-E9 -> 20 | G9: =SUMIF(Pages!B$2:B$101,A9,Pages!Q$2:Q$101) -> 141839
A10: Total | D10: =SUM(D2:D9) -> 201 | E10: =SUM(E2:E9) -> 101 | F10: =SUM(F2:F9) -> 100 | G10: =SUM(G2:G9) -> 1401142

Sheet First 101 pages (latest)
A1: Do on | B1: ID | C1: URL | D1: Live now? | E1: Action | F1: File to paste | G1: Parent page | H1: WP page title | I1: SEO title (Rank Math) | J1: Meta description (Rank Math) | K1: Focus keyword | L1: Words | M1: Status
A2: 46322 | B2: 27 | C2: https://wealthscale.ca/calculators/investment-fee-calculator/ | D2: No | E2: Publish as a new page first, then redirect /calculators/currency-conversion-calculator/ to it | F2: first-101-latest/pages-paste/027-calculators-investment-fee-calculator.html | G2: /calculators/ | H2: Investment Fee Calculator | I2: Investment Fee Calculator: Broker, Robo and MER Costs | J2: Investment fee calculator: yearly costs at 13 Canadian brokers, robo-advisor fees from $185 on $50,000, and what a 2% MER costs $100,000 over 30 years. | K2: investment fee calculator | L2: 8826 | M2: Done
A3: 46322 | B3: 64 | C3: https://wealthscale.ca/compare/best-brokers-for-dividend-investing/ | D3: No | E3: Publish as a new page first, then redirect /compare/best-brokers-low-fx-fees/ to it | F3: first-101-latest/pages-paste/064-compare-best-brokers-for-dividend-investing.html | G3: /compare/ | H3: Best Brokers for Dividend Investing in Canada | I3: Best Broker for Dividend Investing Canada 2026: DRIP Ranking | J3: Best broker for dividend investing Canada ranking for 2026: Questrade leads at 4.3 / 5 with a no-fee fractional DRIP. 7 DRIP brokers scored and compared. | K3: best broker for dividend investing canada | L3: 12564 | M3: Done
A4: 46322 | B4: 97 | C4: https://wealthscale.ca/learn/cipf-vs-cdic/ | D4: No | E4: Publish as a new page first, then redirect /learn/norberts-gambit/ to it | F4: first-101-latest/pages-paste/097-learn-cipf-vs-cdic.html | G4: /learn/ | H4: CIPF vs CDIC | I4: CIPF vs CDIC: Coverage Limits for Investments and Deposits | J4: CIPF vs CDIC explained: CDIC insures eligible deposits up to $100,000 per category, and CIPF covers up to $1,000,000 per account group if a dealer fails. | K4: cipf vs cdic | L4: 8550 | M4: Done
A5: 46322 | B5: 1 | C5: https://wealthscale.ca/ | D5: Yes | E5: Replace the live page | F5: first-101-latest/pages-paste/001-home.html | G5: (none) | H5: Home | I5: Best Investment Platform Canada: Compare Brokers and Rates | J5: Best investment platform Canada: compare 13 online brokers, robo-advisors, savings rates and GICs, with 2026 limits such as the $7,000 TFSA limit. | K5: best investment platform canada | L5: 9033 | M5: Done
A6: 46322 | B6: 2 | C6: https://wealthscale.ca/about/ | D6: Yes | E6: Replace the live page | F6: first-101-latest/pages-paste/002-about.html | G6: (none) | H6: About | I6: WealthScale: About Our CPA Writer and CFA Charterholder | J6: WealthScale compares Canadian investing, savings and bank accounts on real costs. Written by a CPA with 15+ years in tax, reviewed by a CFA charterholder. | K6: wealthscale | L6: 2547 | M6: Done
A7: 46322 | B7: 3 | C7: https://wealthscale.ca/about/sharad-gondaliya/ | D7: Yes | E7: Replace the live page | F7: first-101-latest/pages-paste/003-about-sharad-gondaliya.html | G7: /about/ | H7: Sharad Gondaliya, CPA | I7: Sharad Gondaliya, CPA: Writer and Tax Reviewer | J7: Sharad Gondaliya, CPA writes WealthScale's pages. CPA Ontario No. 61040184, Certified Public Accountant in Washington and Montana, 15+ years in tax. | K7: sharad gondaliya cpa | L7: 1634 | M7: Done
A8: 46322 | B8: 4 | C8: https://wealthscale.ca/editorial-standards/ | D8: Yes | E8: Replace the live page | F8: first-101-latest/pages-paste/004-editorial-standards.html | G8: (none) | H8: Editorial Standards | I8: WealthScale Editorial Standards: How We Write and Check | J8: WealthScale editorial standards: pages written by a CPA with 15+ years in tax, investing pages reviewed by a CFA charterholder, rates re-checked weekly. | K8: wealthscale editorial standards | L8: 2551 | M8: Done
A9: 46322 | B9: 5 | C9: https://wealthscale.ca/how-we-make-money/ | D9: Yes | E9: Replace the live page | F9: first-101-latest/pages-paste/005-how-we-make-money.html | G9: (none) | H9: How We Make Money | I9: WealthScale Advertiser Disclosure: How We Make Money | J9: WealthScale advertiser disclosure: the site has 0 partner links today. Payment will never change which providers we include, their score or their order. | K9: wealthscale advertiser disclosure | L9: 2109 | M9: Done
A10: 46322 | B10: 6 | C10: https://wealthscale.ca/contact/ | D10: Yes | E10: Replace the live page | F10: first-101-latest/pages-paste/006-contact.html | G10: (none) | H10: Contact | I10: Contact WealthScale: Email, Corrections and Media Enquiries | J10: Contact WealthScale at info@wealthscale.ca for questions, corrections and media, or privacy@wealthscale.ca. We aim to reply within 2 business days. | K10: contact wealthscale | L10: 1787 | M10: Done
A11: 46322 | B11: 9 | C11: https://wealthscale.ca/methodology/brokers/ | D11: Yes | E11: Replace the live page | F11: first-101-latest/pages-paste/009-methodology-brokers.html | G11: /methodology/ | H11: Broker Rating Methodology | I11: Broker Rating Methodology: How We Score Canadian Brokers | J11: Our broker rating methodology: six factors with cost weighted 35%, two priced investor profiles and every current score for brokers, robos and banks. | K11: broker rating methodology | L11: 9923 | M11: Done
A12: 46322 | B12: 10 | C12: https://wealthscale.ca/accounts/ | D12: Yes | E12: Replace the live page | F12: first-101-latest/pages-paste/010-accounts.html | G12: (none) | H12: Investment Accounts | I12: Types of Investment Accounts Canada: TFSA, RRSP and More | J12: Types of investment accounts Canada: TFSA, RRSP, FHSA, RESP, RRIF, LIRA and non-registered compared, with 2026 limits like the $7,000 TFSA limit. | K12: types of investment accounts canada | L12: 6322 | M12: Done
A13: 46322 | B13: 11 | C13: https://wealthscale.ca/compare/ | D13: Yes | E13: Replace the live page | F13: first-101-latest/pages-paste/011-compare.html | G13: (none) | H13: Compare Online Brokers | I13: Compare Online Brokers Canada: Fees, Accounts and Scores | J13: Compare online brokers Canada-wide: 13 brokers scored on cost, accounts and US investing. Questrade leads at 4.3 / 5, and seven charge $0 commissions. | K13: compare online brokers canada | L13: 5924 | M13: Done
... A102: 46322 | B102: 8 | C102: https://wealthscale.ca/terms-of-use/ | D102: Yes | E102: Replace the live page (done Oct 27 before the lawyer's written approval; draft note removed) | F102: first-101-latest/pages-paste/008-terms-of-use.html | G102: (none) | H102: Terms of Use and Disclaimer | I102: WealthScale Terms of Use and Disclaimer for Readers | J102: WealthScale terms of use and disclaimer: general information only, not financial, tax or legal advice. Calculators give estimates and rates can change. | K102: wealthscale terms of use | L102: 2135 | M102: Done

Sheet Remove and redirect
A1: Order | B1: Old live URL (remove) | C1: Redirect type | D1: Redirect to (publish this page first) | E1: Why | F1: Status
A2: 1 | B2: https://wealthscale.ca/calculators/currency-conversion-calculator/ | C2: 301 | D2: https://wealthscale.ca/calculators/investment-fee-calculator/ | E2: The old page is no longer part of the site plan; this page takes its place | F2: Done Oct 27: published, 301 added, old page in Trash
A3: 2 | B3: https://wealthscale.ca/compare/best-brokers-low-fx-fees/ | C3: 301 | D3: https://wealthscale.ca/compare/best-brokers-for-dividend-investing/ | E3: The old page is no longer part of the site plan; this page takes its place | F3: Done Oct 27: published, 301 added, old page in Trash
A4: 3 | B4: https://wealthscale.ca/learn/norberts-gambit/ | C4: 301 | D4: https://wealthscale.ca/learn/cipf-vs-cdic/ | E4: The old page is no longer part of the site plan; this page takes its place | F4: Done Oct 27: published, 301 added, old page in Trash

Sheet Widgets
A1: Widget | B1: What it does | C1: New pages using it (IDs) | D1: Number of new pages
A2: tfsa-room | B2: TFSA room from birth year, year became a resident, non-resident years, contributions and withdrawals; shows room now, room next January 1, and a year-by-year table | C2: 133, 134, 135, 148, 189, 190, 192 | D2: =IF(C2="",0,LEN(C2)-LEN(SUBSTITUTE(C2,",",""))+1) -> 7
A3: tfsa-overcontribution | B3: 1% a month tax on an excess TFSA amount | C3: 133, 134 | D3: =IF(C3="",0,LEN(C3)-LEN(SUBSTITUTE(C3,",",""))+1) -> 2
A4: rrsp-room | B4: 2026 RRSP deduction limit from earned income, pension adjustment, carry-forward | C4: 130, 131, 138, 139 | D4: =IF(C4="",0,LEN(C4)-LEN(SUBSTITUTE(C4,",",""))+1) -> 4
A5: rrsp-refund | B5: Tax saved by an RRSP deduction in any province, 2026 brackets | C5: 102, 103, 104, 105, 106, 107, 108, 109, 110, 111, 112, 113, 114, 115, 116, 117, 118, 120, 122, 129, 130, 131, 138, 146, 171, 176, 191, 201 | D5: =IF(C5="",0,LEN(C5)-LEN(SUBSTITUTE(C5,",",""))+1) -> 28
A6: income-tax | B6: 2026 federal and provincial tax, marginal rates by income type | C6: 102, 103, 104, 105, 106, 107, 108, 109, 110, 111, 112, 113, 114, 115, 116, 117, 118, 119, 120, 122, 125, 126, 127, 128, 154, 170, 185, 201 | D6: =IF(C6="",0,LEN(C6)-LEN(SUBSTITUTE(C6,",",""))+1) -> 28
A7: capital-gains | B7: Tax on a capital gain, loss carry-forward | C7: 105, 106, 107, 108, 109, 110, 111, 112, 113, 114, 115, 116, 117, 118, 123, 124, 125, 147, 148 | D7: =IF(C7="",0,LEN(C7)-LEN(SUBSTITUTE(C7,",",""))+1) -> 19
A8: dividend-tax | B8: Tax on eligible and other than eligible dividends | C8: 105, 112, 113, 114, 115, 127, 147, 148, 170 | D8: =IF(C8="",0,LEN(C8)-LEN(SUBSTITUTE(C8,",",""))+1) -> 9
A9: fhsa-room | B9: FHSA participation room by year opened and contributions, lifetime room, closing date | C9: 136, 137, 138 | D9: =IF(C9="",0,LEN(C9)-LEN(SUBSTITUTE(C9,",",""))+1) -> 3
A10: fhsa-eligibility | B10: Four-question FHSA eligibility check | C10: 136 | D10: =IF(C10="",0,LEN(C10)-LEN(SUBSTITUTE(C10,",",""))+1) -> 1
A11: resp-grant | B11: CESG, Additional CESG, Canada Learning Bond, BC and Quebec grants, projection to 17 | C11: 142, 143, 144, 145, 146, 151, 177 | D11: =IF(C11="",0,LEN(C11)-LEN(SUBSTITUTE(C11,",",""))+1) -> 7
A12: rrif-minimum | B12: RRIF minimum withdrawal and projection | C12: 132, 140, 141, 149, 150, 193 | D12: =IF(C12="",0,LEN(C12)-LEN(SUBSTITUTE(C12,",",""))+1) -> 6
A13: hbp-repayment | B13: Home Buyers' Plan repayment schedule | C13: 129, 137, 171, 176 | D13: =IF(C13="",0,LEN(C13)-LEN(SUBSTITUTE(C13,",",""))+1) -> 4
A14: first-home | B14: FHSA plus Home Buyers' Plan funds for one buyer or a couple | C14: 136, 137, 173, 174 | D14: =IF(C14="",0,LEN(C14)-LEN(SUBSTITUTE(C14,",",""))+1) -> 4
A15: tfsa-vs-rrsp | B15: After-tax comparison using marginal rates now and later | D15: =IF(C15="",0,LEN(C15)-LEN(SUBSTITUTE(C15,",",""))+1) -> 0
A16: account-chooser | B16: Which registered accounts fit a goal (general information) | C16: 102 | D16: =IF(C16="",0,LEN(C16)-LEN(SUBSTITUTE(C16,",",""))+1) -> 1
A17: us-withholding | B17: US dividend withholding by Canadian account type | C17: 128, 147 | D17: =IF(C17="",0,LEN(C17)-LEN(SUBSTITUTE(C17,",",""))+1) -> 2
A18: broker-cost | B18: Yearly cost at every broker for a trading pattern | C18: 176, 182, 183, 184, 186, 187, 188, 190, 191, 194, 195 | D18: =IF(C18="",0,LEN(C18)-LEN(SUBSTITUTE(C18,",",""))+1) -> 11
A19: options-cost | B19: Yearly options commissions by broker | C19: 179, 184, 188 | D19: =IF(C19="",0,LEN(C19)-LEN(SUBSTITUTE(C19,",",""))+1) -> 3
A20: margin-interest | B20: Margin interest by broker | C20: 178, 188, 194 | D20: =IF(C20="",0,LEN(C20)-LEN(SUBSTITUTE(C20,",",""))+1) -> 3
A21: robo-fee | B21: Yearly robo-advisor fees for an amount | C21: 192, 193 | D21: =IF(C21="",0,LEN(C21)-LEN(SUBSTITUTE(C21,",",""))+1) -> 2
A22: fee-drag | B22: What a higher fee costs over time | C22: 186, 190, 191, 192, 193 | D22: =IF(C22="",0,LEN(C22)-LEN(SUBSTITUTE(C22,",",""))+1) -> 5
A23: compound-interest | B23: Growth with monthly contributions, year-by-year | C23: 135, 142, 144, 165, 167, 168, 200 | D23: =IF(C23="",0,LEN(C23)-LEN(SUBSTITUTE(C23,",",""))+1) -> 7
A24: savings-goal | B24: Monthly saving needed for a target | C24: 143, 145, 167, 168, 196, 200 | D24: =IF(C24="",0,LEN(C24)-LEN(SUBSTITUTE(C24,",",""))+1) -> 6
A25: gic-calc | B25: GIC maturity value and tax | C25: 166 | D25: =IF(C25="",0,LEN(C25)-LEN(SUBSTITUTE(C25,",",""))+1) -> 1
A26: gic-ladder | B26: 1 to 5-year GIC ladder | C26: 166 | D26: =IF(C26="",0,LEN(C26)-LEN(SUBSTITUTE(C26,",",""))+1) -> 1
A27: hisa-earnings | B27: Interest at each savings account (or USD account) | C27: 167, 180, 199 | D27: =IF(C27="",0,LEN(C27)-LEN(SUBSTITUTE(C27,",",""))+1) -> 3
A28: card-cashback | B28: Net cash back after card fees | D28: =IF(C28="",0,LEN(C28)-LEN(SUBSTITUTE(C28,",",""))+1) -> 0
A29: deposit-insurance | B29: CDIC coverage by deposit category | C29: 166, 197, 198, 199 | D29: =IF(C29="",0,LEN(C29)-LEN(SUBSTITUTE(C29,",",""))+1) -> 4
A30: chequing-cost | B30: Yearly fees and interest at each chequing account | C30: 181, 196, 197, 198, 199 | D30: =IF(C30="",0,LEN(C30)-LEN(SUBSTITUTE(C30,",",""))+1) -> 5
A31: crypto-fee | B31: Trading fees at each authorized crypto platform | D31: =IF(C31="",0,LEN(C31)-LEN(SUBSTITUTE(C31,",",""))+1) -> 0
A32: ws-tier | B32: Wealthsimple tier and perks by assets | C32: 176, 177, 178, 179, 180, 181 | D32: =IF(C32="",0,LEN(C32)-LEN(SUBSTITUTE(C32,",",""))+1) -> 6
A33: benefit-dates | B33: Next payment date countdown and full schedule | C33: 151, 152, 153, 155, 156, 157, 158, 159, 160, 161, 162, 163, 164, 169, 181 | D33: =IF(C33="",0,LEN(C33)-LEN(SUBSTITUTE(C33,",",""))+1) -> 15
A34: oas-clawback | B34: OAS recovery tax | C34: 126, 127, 150, 153, 154, 158, 165 | D34: =IF(C34="",0,LEN(C34)-LEN(SUBSTITUTE(C34,",",""))+1) -> 7
A35: cpp-start-age | B35: CPP and OAS by start age 60 to 70 | C35: 121, 156, 157, 165 | D35: =IF(C35="",0,LEN(C35)-LEN(SUBSTITUTE(C35,",",""))+1) -> 4
A36: gst-credit | B36: GST/HST credit estimate | D36: =IF(C36="",0,LEN(C36)-LEN(SUBSTITUTE(C36,",",""))+1) -> 0
A37: rrsp-withdrawal | B37: Withholding tax and final tax on an RRSP withdrawal | C37: 129, 132, 139, 150, 171 | D37: =IF(C37="",0,LEN(C37)-LEN(SUBSTITUTE(C37,",",""))+1) -> 5
A38: tax-software-picker | B38: Tax software that fits a return | C38: 185, 201 | D38: =IF(C38="",0,LEN(C38)-LEN(SUBSTITUTE(C38,",",""))+1) -> 2
A39: broker-match | B39: Filter brokers by features, ranked by score | C39: 182, 183, 186, 187, 188, 189, 194, 195 | D39: =IF(C39="",0,LEN(C39)-LEN(SUBSTITUTE(C39,",",""))+1) -> 8
A40: transfer-fee | B40: Transfer-out fees and which brokers cover them | C40: 182, 183, 184 | D40: =IF(C40="",0,LEN(C40)-LEN(SUBSTITUTE(C40,",",""))+1) -> 3
...

Sheet Open items
A1: # | B1: Item | C1: Owner | D1: Why it matters | E1: Status
A2: 1 | B2: CPA review of the standard rules stated on pages 102 to 201 without a register entry (the full list, page by page, is in factcheck-notes-next100.md in this package). | C2: Sharad | D2: Rules are worded generally on the pages; confirm or ask for a change before Day 6. | E2: Open
A3: 2 | B3: 2026 dividend tax credit rates are not yet verified for Alberta, Saskatchewan, Manitoba, Yukon, the Northwest Territories and Nunavut. Pages and calculators show 'being confirmed' for these six. | C3: Sharad | D3: Adding the six rates turns dividend figures on for every province. | E3: Open
A4: 3 | B4: Pages state the 2026 tax-year dates set by the Income Tax Act: RRSP contributions by March 1, 2027 (the 60th day of 2027), most returns and all balances by April 30, 2027, and June 15, 2027 for the self-employed. The CRA has not yet published its important-dates page for the 2026 tax year. | C4: Navneet | D4: Check the CRA page when it is published; change a page only if a date differs. | E4: Open
A5: 4 | B5: Bank offers on pages 196 to 200 were checked on October 23, 2026; most big-bank offers end between October 29 and November 3, 2026. | C5: Navneet | D5: Check each offer's end date the morning the page goes live and remove any that have ended. | E5: Open
A6: 5 | B6: Canada Disability Benefit thresholds for July 2026 to June 2027 ($23,483 single, $33,182.50 couple) are calculated from the regulation's indexing factor; the government's benefit page still shows $23,000 and $32,500. | C6: Sharad | D6: Confirm the method or switch to the page's figures. | E6: Open
A7: 6 | B7: Canada Workers Benefit 2026 income end points are not published by the CRA; pages show them only as our calculation from the published rates. | C7: Sharad | D7: Replace with the CRA's figures when published. | E7: Open
A8: 7 | B8: Alberta land titles fee: the schedule does not say whether the $5 per $5,000 is charged on part of $5,000. The calculator counts full $5,000 steps. | C8: Navneet | D8: Change one line in the land transfer calculator if Alberta confirms it rounds up. | E8: Open
A9: 8 | B9: CMHC's 0.20% premium surcharge: confirmed for first-time buyers choosing 30 years (2024 notice); its scope after the December 15, 2024 expansion to all first-time buyers and new builds is not stated on an official page. | C9: Sharad | D9: The mortgage calculators add 0.20% to every insured 30-year amortization. | E9: Open
A10: 9 | B10: 2027 payment dates for the CCB, Canada Disability Benefit, Ontario Trillium Benefit and advance Canada Workers Benefit are not yet published. | C10: Navneet | D10: Add the dates to the benefit pages and the payment-date calculator when published. | E10: Open
A11: 10 | B11: Wealthsimple's own pages conflict on several figures (USD prime for margin, options strategies by account, account number length, early pay timing, registered and USD savings rates, Wealthsimple Tax Pro return count). Pages give both values or leave the point out. | C11: Navneet | D11: Re-check after Wealthsimple's November 5, 2026 event and settle each conflict. | E11: Open
A12: 11 | B12: Quebec take-home pay: the calculator values Quebec non-refundable amounts at the 14% lowest rate; Revenu Quebec does not state the conversion rate in words on the pages opened. | C12: Sharad | D12: Confirm the 14% assumption. | E12: Open
A13: 12 | B13: Superficial loss with a partial buy-back: the denial formula is not stated in the Income Tax Act or on a CRA page opened. The checker flags a partial case without computing the denied part. | C13: Sharad | D13: Add the formula to the calculator if confirmed. | E13: Open
... A18: 17 | B18: The tax engine and calculators include the Ontario and B.C. low-income tax reductions only. New Brunswick, Nova Scotia, Prince Edward Island and Newfoundland and Labrador also have low-income reductions, which are not in the verified registers, so tax for those provinces at incomes from $20,000 to $40,000 may be overstated. The pages say that only the basic personal amounts are counted. | C18: Sharad | D18: Verify the four provinces' 2026 reduction amounts and income thresholds; one data change then corrects every calculator and table. | E18: Open
